Workbook

Sheet _README
A1: BONITE BOTTLERS LIMITED
A2: SFA — SAP Integration & Compliance Module
A4: Purpose of This Workbook
A5: A working model that demonstrates the complete logic of the SAP Integration & Compliance module.
A6: Used to validate design before development begins; will serve as the developer reference and UAT data set.
A8: Sheet Index
A9: Sheet | B9: Type | C9: Purpose
A10: _README | B10: Info | C10: This page
A11: M_Depot | B11: Master | C11: Depot Master — codes, default outlets, SAP warehouse
A12: M_SKU | B12: Master | C12: SKU Master — code, name, category, pack size, retail price
A13: M_DepotPrice | B13: Master | C13: Depot-wise default price for shortage postings
A14: M_User | B14: Master | C14: User Master — salesman, SAP code, depot, reporting manager
A15: M_Config | B15: Master | C15: System parameters — SLA, aging threshold, etc.
A16: T_Load | B16: Transaction | C16: Every SAP-pushed load. Status: Pending / Confirmed / Force-Pushed
A17: T_Sales | B17: Transaction | C17: Every sale recorded on mobile
A18: T_Unload | B18: Transaction | C18: Every unload event (derived from Load − Sales)
A19: T_ROP | B19: Transaction | C19: ROP verification — Expected vs Actual, Variance, Action
A20: T_DefaultOutletPosting | B20: Transaction | C20: Auto-postings to Default Outlet for shortages
... A25: R_AgingView | B25: Report | C25: Open loads aged by days outstanding
A27: How to Read This Workbook
A28: • Sheets starting with M_ are MASTER data (configured once).
A29: • Sheets starting with T_ are TRANSACTIONAL data (daily activity).
A30: • Sheets starting with R_ are REPORTS or VIEWS (auto-calculated from M_ and T_ sheets).
A31: • Sheets starting with _ are workbook-level helpers (README, scenario control).

Sheet M_Depot
A1: Depot Master
A2: Source of truth for depot codes, default outlets, and SAP warehouse references.
A3: NOTE: In the live SFA system, Default Outlet is maintained in Outlet Master (with "Default Outlet" flag checked).
A4: Repeated here purely for Excel-model convenience.
A6: Depot Name | B6: Depot Code | C6: Default Outlet Code | D6: Default Outlet Name | E6: SAP Warehouse | F6: Status
A7: Mwanza | B7: MWZ | C7: MWZ1000001 | D7: Mwanza Ambush | E7: MWZFWH | F7: Active
A8: Dodoma | B8: DOD | C8: DOD1000001 | D8: Dodoma Ambush | E8: DODFWH | F8: Active
A9: Mbeya | B9: MBY | C9: MBY1000001 | D9: Mbeya Ambush | E9: MBYFWH | F9: Active
A10: Dar Es Salaam | B10: DAR | C10: DAR1000001 | D10: Dar Es Salaam Ambush | E10: DARFWH | F10: Active
A11: Same | B11: SAM | C11: SAM1000001 | D11: Same Ambush | E11: SAMFWH | F11: Active
A12: Mererani | B12: MER | C12: MER1000001 | D12: Mererani Ambush | E12: MERFWH | F12: Active
A13: Tarakea | B13: TRK | C13: TRK1000001 | D13: Tarakea Ambush | E13: TRKFWH | F13: Active
A14: Tanga | B14: TAN | C14: TAN1000001 | D14: Tanga Ambush | E14: TANFWH | F14: Active
A15: Nzega | B15: NZG | C15: NZG1000001 | D15: Nzega Ambush | E15: NZGFWH | F15: Active
A16: Terrat | B16: TER | C16: TER1000001 | D16: Terrat Ambush | E16: TERFWH | F16: Active
A17: Kiteto | B17: KIT | C17: KIT1000001 | D17: Kiteto Ambush | E17: KITFWH | F17: Active
... A24: MOSHI | B24: MOS | C24: MOS1000001 | D24: MOSHI Ambush | E24: MOSFWH | F24: Active
A26: Total Active Depots: | B26: =COUNTIF(F7:F24,"Active") -> 18

Sheet M_SKU
A1: SKU (Product) Master
A2: Product attributes only. Pricing is maintained in M_DepotPrice (single source of truth for pricing).
A4: Code Prefix Legend
A5: FG - Finished Goods — RGB CSD (Returnable Glass Bottles, Carbonated Soda)
A6: KD - KNMW — Kilimanjaro Natural Mineral Water (PET and Bulk)
A7: PH - PET 500ml CSD
A8: PO - PET 300ml CSD (small-format)
A9: PT - PET 1250ml CSD (large-format / tall)
A11: Unit / Sub-Unit Rule
A12: • When Unit = Sub-Unit (Conversion = 1): product sells in whole Units only.
A13: • When Unit ≠ Sub-Unit (Conversion > 1): product can be sold in whole Units OR loose Sub-Units. Salesman toggles view on mobile.
A14: • Loads are always in whole Units. Unloads and sales may include decimals for sub-unit-capable SKUs.
A15: Example: 12 Crates + 16 Bottles of a 24/Crate SKU is stored as 12.6667 Crates internally.
A17: Product Name | B17: Code | C17: Category | D17: Sub-Category | E17: Brand | F17: Unit | G17: Sub Unit | H17: Conversion Rate | I17: Is Active | J17: Sells in Sub-Unit?
A18: Coke RGB 350ml | B18: FG001 | C18: Carbonated Soda Drink (CSD) | D18: RETURNABLE GLASS BOTTLES (RGB) | E18: COKE | F18: Crates | G18: Bottles | H18: 24 | I18: Y | J18: =IF(F18=G18,"No","Yes") -> Yes
A19: Fanta Orange RGB 350ml | B19: FG002 | C19: Carbonated Soda Drink (CSD) | D19: RETURNABLE GLASS BOTTLES (RGB) | E19: FANTA | F19: Crates | G19: Bottles | H19: 24 | I19: Y | J19: =IF(F19=G19,"No","Yes") -> Yes
A20: Fanta Passion RGB 350ml | B20: FG003 | C20: Carbonated Soda Drink (CSD) | D20: RETURNABLE GLASS BOTTLES (RGB) | E20: FANTA | F20: Crates | G20: Bottles | H20: 24 | I20: Y | J20: =IF(F20=G20,"No","Yes") -> Yes
A21: Fanta Pineapple RGB 350ml | B21: FG004 | C21: Carbonated Soda Drink (CSD) | D21: RETURNABLE GLASS BOTTLES (RGB) | E21: FANTA | F21: Crates | G21: Bottles | H21: 24 | I21: Y | J21: =IF(F21=G21,"No","Yes") -> Yes
A22: Fanta Fruit Blast RGB 350 ml | B22: FG005 | C22: Carbonated Soda Drink (CSD) | D22: RETURNABLE GLASS BOTTLES (RGB) | E22: FANTA | F22: Crates | G22: Bottles | H22: 24 | I22: Y | J22: =IF(F22=G22,"No","Yes") -> Yes
A23: Sprite 350ml | B23: FG006 | C23: Carbonated Soda Drink (CSD) | D23: RETURNABLE GLASS BOTTLES (RGB) | E23: SPRITE | F23: Crates | G23: Bottles | H23: 24 | I23: Y | J23: =IF(F23=G23,"No","Yes") -> Yes
A24: Stoney Tangawizi RGB 350ml | B24: FG007 | C24: Carbonated Soda Drink (CSD) | D24: RETURNABLE GLASS BOTTLES (RGB) | E24: STONEY | F24: Crates | G24: Bottles | H24: 24 | I24: Y | J24: =IF(F24=G24,"No","Yes") -> Yes
A25: Sparletta Pinenut RGB 350ml | B25: FG008 | C25: Carbonated Soda Drink (CSD) | D25: RETURNABLE GLASS BOTTLES (RGB) | E25: SPARLETTA | F25: Crates | G25: Bottles | H25: 24 | I25: Y | J25: =IF(F25=G25,"No","Yes") -> Yes
A26: Krest Bitter Lemon RGB 300ml | B26: FG009 | C26: Carbonated Soda Drink (CSD) | D26: RETURNABLE GLASS BOTTLES (RGB) | E26: KREST | F26: Crates | G26: Bottles | H26: 24 | I26: Y | J26: =IF(F26=G26,"No","Yes") -> Yes
A27: Krest Club Soda RGB 300ml | B27: FG010 | C27: Carbonated Soda Drink (CSD) | D27: RETURNABLE GLASS BOTTLES (RGB) | E27: KREST | F27: Crates | G27: Bottles | H27: 24 | I27: Y | J27: =IF(F27=G27,"No","Yes") -> Yes
A28: Krest Tonic Water RGB 300ml | B28: FG011 | C28: Carbonated Soda Drink (CSD) | D28: RETURNABLE GLASS BOTTLES (RGB) | E28: KREST | F28: Crates | G28: Bottles | H28: 24 | I28: Y | J28: =IF(F28=G28,"No","Yes") -> Yes
A29: Krest Ginger Ale RGB 300ml | B29: FG012 | C29: Carbonated Soda Drink (CSD) | D29: RETURNABLE GLASS BOTTLES (RGB) | E29: KREST | F29: Crates | G29: Bottles | H29: 24 | I29: Y | J29: =IF(F29=G29,"No","Yes") -> Yes
... A57: Fanta Orange Pet 1250 ML | B57: PT007 | C57: Carbonated Soda Drink (CSD) | D57: PET CSD | E57: FANTA | F57: Cases | G57: Cases | H57: 1 | I57: Y | J57: =IF(F57=G57,"No","Yes") -> No
A59: Total Active SKUs: | B59: =COUNTIF(I18:I57,"Y") -> 40
A60: SKUs Sold in Sub-Units: | B60: =COUNTIF(J18:J57,"Yes") -> 15
A61: SKUs Sold Only in Whole Units: | B61: =COUNTIF(J18:J57,"No") -> 25

Sheet M_DepotPrice
A1: Depot-wise Price Master
A2: Single source of truth for pricing. Used for shortage postings to Default Outlet and all sales reporting in this model.
A4: Lookup Cascade (Shortage Posting Logic)
A5: 1. First look for a row where Price Type = "Special" AND Code = X AND Depot Applicable = Y.
A6: 2. If found → use that special price.
A7: 3. If not found → fall back to the row where Price Type = "Default" AND Code = X AND Depot Applicable = "All".
A9: Code | B9: SKU Name | C9: Unit Price | D9: Conversion Rate | E9: Sub-Unit Price | F9: Tax % | G9: Price Type | H9: Depot Applicable
A10: FG001 | B10: =M_SKU!A18 -> Coke RGB 350ml | C10: 11780 | D10: =M_SKU!H18 -> 24 | E10: =IF(D10=1,"",ROUND(C10/D10,2)) -> 490.83 | F10: 0.18 | G10: Default | H10: All
A11: FG002 | B11: =M_SKU!A19 -> Fanta Orange RGB 350ml | C11: 11780 | D11: =M_SKU!H19 -> 24 | E11: =IF(D11=1,"",ROUND(C11/D11,2)) -> 490.83 | F11: 0.18 | G11: Default | H11: All
A12: FG003 | B12: =M_SKU!A20 -> Fanta Passion RGB 350ml | C12: 11780 | D12: =M_SKU!H20 -> 24 | E12: =IF(D12=1,"",ROUND(C12/D12,2)) -> 490.83 | F12: 0.18 | G12: Default | H12: All
A13: FG004 | B13: =M_SKU!A21 -> Fanta Pineapple RGB 350ml | C13: 11780 | D13: =M_SKU!H21 -> 24 | E13: =IF(D13=1,"",ROUND(C13/D13,2)) -> 490.83 | F13: 0.18 | G13: Default | H13: All
A14: FG005 | B14: =M_SKU!A22 -> Fanta Fruit Blast RGB 350 ml | C14: 11780 | D14: =M_SKU!H22 -> 24 | E14: =IF(D14=1,"",ROUND(C14/D14,2)) -> 490.83 | F14: 0.18 | G14: Default | H14: All
A15: FG006 | B15: =M_SKU!A23 -> Sprite 350ml | C15: 11780 | D15: =M_SKU!H23 -> 24 | E15: =IF(D15=1,"",ROUND(C15/D15,2)) -> 490.83 | F15: 0.18 | G15: Default | H15: All
A16: FG007 | B16: =M_SKU!A24 -> Stoney Tangawizi RGB 350ml | C16: 11780 | D16: =M_SKU!H24 -> 24 | E16: =IF(D16=1,"",ROUND(C16/D16,2)) -> 490.83 | F16: 0.18 | G16: Default | H16: All
A17: FG008 | B17: =M_SKU!A25 -> Sparletta Pinenut RGB 350ml | C17: 11780 | D17: =M_SKU!H25 -> 24 | E17: =IF(D17=1,"",ROUND(C17/D17,2)) -> 490.83 | F17: 0.18 | G17: Default | H17: All
A18: FG009 | B18: =M_SKU!A26 -> Krest Bitter Lemon RGB 300ml | C18: 11780 | D18: =M_SKU!H26 -> 24 | E18: =IF(D18=1,"",ROUND(C18/D18,2)) -> 490.83 | F18: 0.18 | G18: Default | H18: All
A19: FG010 | B19: =M_SKU!A27 -> Krest Club Soda RGB 300ml | C19: 11780 | D19: =M_SKU!H27 -> 24 | E19: =IF(D19=1,"",ROUND(C19/D19,2)) -> 490.83 | F19: 0.18 | G19: Default | H19: All
A20: FG011 | B20: =M_SKU!A28 -> Krest Tonic Water RGB 300ml | C20: 11780 | D20: =M_SKU!H28 -> 24 | E20: =IF(D20=1,"",ROUND(C20/D20,2)) -> 490.83 | F20: 0.18 | G20: Default | H20: All
A21: FG012 | B21: =M_SKU!A29 -> Krest Ginger Ale RGB 300ml | C21: 11780 | D21: =M_SKU!H29 -> 24 | E21: =IF(D21=1,"",ROUND(C21/D21,2)) -> 490.83 | F21: 0.18 | G21: Default | H21: All
... A49: PT007 | B49: =M_SKU!A57 -> Fanta Orange Pet 1250 ML | C49: 8305 | D49: =M_SKU!H57 -> 1 | E49: =IF(D49=1,"",ROUND(C49/D49,2)) | F49: 0.18 | G49: Default | H49: All
A50: — Special Prices —
A51: KD003 | B51: =M_SKU!A34 -> KNMW 1500ml | C51: 3559 | D51: =M_SKU!H34 -> 1 | E51: =IF(D51=1,"",ROUND(C51/D51,2)) | F51: 0.18 | G51: Special | H51: Dar Es Salaam
A52: KD007 | B52: =M_SKU!A38 -> KNMW 1000ml(6 Pack) | C52: 2119 | D52: =M_SKU!H38 -> 1 | E52: =IF(D52=1,"",ROUND(C52/D52,2)) | F52: 0.18 | G52: Special | H52: Dar Es Salaam
A54: Default Price Rows: | C54: =COUNTIF(G10:G52,"Default") -> 40
A55: Special Price Rows: | C55: =COUNTIF(G10:G52,"Special") -> 2
A57: Price Lookup Demo
A58: Demonstrates the cascade: enter SKU + Depot below to see the resolved price.
A60: SKU Code: | C60: KD007
A61: Depot: | C61: Dar Es Salaam
A62: Resolved Price: | C62: {=IFERROR(INDEX(C10:C52,MATCH(1,(A10:A52=C60)*(H10:H52=C61)*(G10:G52="Special"),0)),INDEX(C10:C52,MATCH(1,(A10:A52=C60)*(G10:G52="Default"),0)))} -> 2119 | D62: {=_xlfn.LET(_xlpm.Special,_xlfn._xlws.FILTER($C$10:$C$52,($A$10:$A$52=C60)*($G$10:$G$52="Special")*($H$10:$H$52=C61),""),_xlpm.Default,_xlfn._xlws.FILTER($C$10:$C$52,($A$10:$A$52=C60)*($G$10:$G$52="Default"),""),IF(_xlpm.Special<>"",_xlpm.Special,_xlpm.Default))} -> 2119
A63: Source: | B63: =IFERROR(IF(INDEX(G10:G52,MATCH(1,(A10:A52=C60)*(H10:H52=C61)*(G10:G52="Special"),0))="Special","Special (depot override)","Default"),"Default") -> Default
A65: Note: Formulas above use INDEX/MATCH with multiple conditions; works in Excel 365 / 2021+. For older Excel, use as array formula (Ctrl+Shift+Enter).

Sheet M_User
A1: User Master
A2: All users in scope for the SAP Integration & Compliance model: Salesmen, Sales Supervisors, and Clerks.
A4: Notes
A5: • Salesmen: SAP-pushed loads map to these users via SAP Code. They appear on mobile, sell, and unload.
A6: • Sales Supervisors: receive variance reports for salesmen reporting to them (parallel 24h SLA logging).
A7: • Clerks: confirm SAP-pushed invoices in the Integration page; verify Actual ROP at end of day.
A8: • Rows highlighted yellow = Sales Supervisors. Rows highlighted green = Clerks. Plain rows = Salesmen.
A9: • "BBL_SUP_***" and "BBL_CLK_***" Emp Codes are placeholders to be replaced with real codes before go-live.
A11: User ID | B11: Emp Code | C11: User Name | D11: SAP Code | E11: Depot Code | F11: Role | G11: Reporting Manager | H11: Reporting Mgr User ID | I11: Reporting Manager Email | J11: Is Active
A12: 89 | B12: BBL2211 | C12: Omary O. Seif | D12: DSM300140 | E12: DAR | F12: Salesman | G12: Rose Meshack Kambey | H12: 86 | I12: Rose.Meshack@bbl.co.tz | J12: Y
A13: 88 | B13: BBL2446 | C13: Doglas E. Shirima | D13: ARS000069 | E13: ARS | F13: Salesman | G13: Kelvin V. Kuwese | H13: 79 | I13: Kelvin.Kuwese@bbl.co.tz | J13: Y
A14: 76 | B14: BBL2769 | C14: Gloria Florence Temba | D14: MOS100535 | E14: MOS | F14: Salesman | G14: Rachel Emanuel Kissota | H14: 57 | I14: Rachel.Kissota@bbl.co.tz | J14: Y
A15: 75 | B15: BBL2916 | C15: Nickson Zakaria Soingei | D15: MOS100658 | E15: MOS | F15: Salesman | G15: Rachel Emanuel Kissota | H15: 57 | I15: Rachel.Kissota@bbl.co.tz | J15: Y
A16: 74 | B16: MSL960 | C16: Ritha Nemes Sambaya | D16: MOS100639 | E16: MOS | F16: Salesman | G16: Rachel Emanuel Kissota | H16: 57 | I16: Rachel.Kissota@bbl.co.tz | J16: Y
A17: 73 | B17: BBL1959 | C17: George Gibson Mmary | D17: MOS100200 | E17: MOS | F17: Salesman | G17: Rachel Emanuel Kissota | H17: 57 | I17: Rachel.Kissota@bbl.co.tz | J17: Y
A18: 72 | B18: BBL1183 | C18: Erick K. Mkama | D18: MOS100209 | E18: MOS | F18: Salesman | G18: Rachel Emanuel Kissota | H18: 57 | I18: Rachel.Kissota@bbl.co.tz | J18: Y
A19: 71 | B19: BBL1723 | C19: Frank Samwel Kahewanga | D19: MOS100215 | E19: MOS | F19: Salesman | G19: Rachel Emanuel Kissota | H19: 57 | I19: Rachel.Kissota@bbl.co.tz | J19: Y
A20: 70 | B20: BBL1759 | C20: Seleman Abdalah Mshana | D20: MOS100171 | E20: MOS | F20: Salesman | G20: Moses Titus Shija | H20: 56 | I20: Moses.Shija@bbl.co.tz | J20: Y
A21: 69 | B21: MSL1118 | C21: Samson Felix Ngowi | D21: MOS100842 | E21: MOS | F21: Salesman | G21: Moses Titus Shija | H21: 56 | I21: Moses.Shija@bbl.co.tz | J21: Y
A22: 68 | B22: BBL2732 | C22: Emmanueli Steven John | D22: MOS100633 | E22: MOS | F22: Salesman | G22: Maria M. Mchagi | H22: 55 | I22: Maria.Mchagi@bbl.co.tz | J22: Y
A23: 67 | B23: BBL1963 | C23: Priscus J Justine | D23: MOS100022 | E23: MOS | F23: Salesman | G23: Moses Titus Shija | H23: 56 | I23: Moses.Shija@bbl.co.tz | J23: Y
... A44: 29 | B44: BBL2285 | C44: Piniel Julius Singo | D44: MOS100654 | E44: MOS | F44: Salesman | G44: Steven Olais Kivuyo | H44: 28 | I44: stephen.kivuyo@bbl.co.tz | J44: Y
A45: 28 | B45: BBL_SUP_028 | C45: Steven Olais Kivuyo | E45: MOS | F45: Sales Supervisor | I45: stephen.kivuyo@bbl.co.tz | J45: Y
A46: 46 | B46: BBL_SUP_046 | C46: Beatrice Urio | E46: MOS | F46: Sales Supervisor | I46: Beatrice.Urio@bbl.co.tz | J46: Y
A47: 47 | B47: BBL_SUP_047 | C47: Stephen F. Njama | E47: MOS | F47: Sales Supervisor | I47: Stephen.Njama@bbl.co.tz | J47: Y
A48: 55 | B48: BBL_SUP_055 | C48: Maria M. Mchagi | E48: MOS | F48: Sales Supervisor | I48: Maria.Mchagi@bbl.co.tz | J48: Y
A49: 56 | B49: BBL_SUP_056 | C49: Moses Titus Shija | E49: MOS | F49: Sales Supervisor | I49: Moses.Shija@bbl.co.tz | J49: Y
A50: 57 | B50: BBL_SUP_057 | C50: Rachel Emanuel Kissota | E50: MOS | F50: Sales Supervisor | I50: Rachel.Kissota@bbl.co.tz | J50: Y
A51: 79 | B51: BBL_SUP_079 | C51: Kelvin V. Kuwese | E51: ARS | F51: Sales Supervisor | I51: Kelvin.Kuwese@bbl.co.tz | J51: Y
A52: 86 | B52: BBL_SUP_086 | C52: Rose Meshack Kambey | E52: DAR | F52: Sales Supervisor | I52: Rose.Meshack@bbl.co.tz | J52: Y
A53: C001 | B53: BBL_CLK_001 | C53: Clerk — Dar Es Salaam | E53: DAR | F53: Clerk | J53: Y
A54: C002 | B54: BBL_CLK_002 | C54: Clerk — Arusha | E54: ARS | F54: Clerk | J54: Y
A55: C003 | B55: BBL_CLK_003 | C55: Clerk — Moshi | E55: MOS | F55: Clerk | J55: Y
A57: Total Users: | C57: =COUNTA(A12:A55) -> 44
A58: - Salesmen: | C58: =COUNTIF(F12:F55,"Salesman") -> 33
A59: - Sales Supervisors: | C59: =COUNTIF(F12:F55,"Sales Supervisor") -> 8
A60: - Clerks: | C60: =COUNTIF(F12:F55,"Clerk") -> 3
A62: Active Users: | C62: =COUNTIF(J12:J55,"Y") -> 44
A64: Data Integrity Checks
A65: Duplicate SAP Codes: | C65: =SUMPRODUCT((D12:D55<>"")*(COUNTIF(D12:D55,D12:D55)>1)) -> 0
...

Sheet M_Config
A1: System Configuration
A2: Global parameters used throughout the model. Editable inputs are highlighted in pale yellow.
A3: Live system equivalent: System Settings page in SFA Web, accessible to authorised admin only.
A5: SAP Integration & Compliance Parameters
A6: Parameter | B6: Value | C6: Unit | D6: Notes
A7: Reason Logging SLA | B7: 24 | C7: Hours | D7: Supervisor must log variance reason within this window; aged variances flagged for management.
A8: Aging Alert Threshold | B8: 7 | C8: Days | D8: Open loads outstanding beyond this threshold appear in the Aging View as stale loads.
A9: Force-Push Approval Required | B9: No | D9: Clerk authority is sufficient to force-push an unmapped SAP invoice. Controlled via Roles & Permissions.
A10: Geo-Fence Radius | B10: 100 | C10: Metres | D10: Reference value from main pilot. Used for delivery and outlet visit validation; not used directly here.
A11: Variance Tolerance | B11: 0 | C11: Units | D11: Zero tolerance: any non-zero variance between Expected ROP and Actual ROP triggers a variance report.
A12: Default Outlet Price Source | B12: Depot Default Price | D12: Pricing source for shortage postings. Looked up via the M_DepotPrice cascade.
A13: Pricing Cascade Order | B13: Special → Default | D13: For shortage postings: try Special price first (Depot+SKU), then fall back to Default (SKU, All depots).
A14: Model Currency | B14: TZS | D14: Tanzanian Shilling. Used for all monetary displays in this model.
A16: Color Coding
A17: Pale Yellow + Blue Bold | B17: Editable input parameter

Sheet T_Load
A1: T_Load — SAP Integration Page (Inbound)
A2: Every SAP-pushed invoice (van load) lands here. Each row = one SKU+Batch line. Rows with the same Load ID belong to the same SAP document.
A3: Clerk reviews each Load ID and either Confirms (auto-mapped) or Force-Pushes (if SAP Code does not resolve in User Master).
A4: Once Confirmed, the load flows into Van Load (the salesman sees stock on his mobile).
A6: Column Groups: | B6: Identification | D6: From SAP | F6: Resolved by SFA | H6: State | J6: Exception Handling | L6: Derived Key
A8: Load ID | B8: SAP Doc Number | C8: Posting/Load Date | D8: SAP Code | E8: SAP Dest Name | F8: Mapped User ID | G8: Mapped Salesman Name | H8: Mapped Depot | I8: SAP Warehouse Code | J8: SKU Code | K8: SKU Name | L8: Batch Number | M8: Production Date | N8: Expiry Date | O8: Quantity (Units) | P8: Status | Q8: Confirmed By | R8: Confirmed On | S8: Force-Push Reason | T8: Remarks | U8: Stock Key
A9: L-0001 | B9: 166147 | C9: 46179 | D9: MOS100802 | E9: Joyline J Lyimo | F9: =IFERROR(INDEX(M_User!$A$12:$J$67,MATCH(D9,M_User!$D$12:$D$67,0),1),"UNMAPPED") -> 45 | G9: =IFERROR(INDEX(M_User!$A$12:$J$67,MATCH(D9,M_User!$D$12:$D$67,0),3),"UNMAPPED") -> Joyline J Lyimo | H9: =IFERROR(INDEX(M_User!$A$12:$J$67,MATCH(D9,M_User!$D$12:$D$67,0),5),"UNMAPPED") -> MOS | I9: MOSFWH | J9: PH001 | K9: =IFERROR(INDEX(M_SKU!$A$18:$J$57,MATCH(J9,M_SKU!$B$18:$B$57,0),1),"UNKNOWN SKU") -> Coke Pet 500ML ( x12) | L9: CK6-33411 | M9: 46177 | N9: 46288 | O9: 70 | P9: Pending Confirmation | U9: =D9 & "|" & J9 & "|" & L9 -> MOS100802|PH001|CK6-33411
A10: L-0001 | B10: 166147 | C10: 46179 | D10: MOS100802 | E10: Joyline J Lyimo | F10: =IFERROR(INDEX(M_User!$A$12:$J$67,MATCH(D10,M_User!$D$12:$D$67,0),1),"UNMAPPED") -> 45 | G10: =IFERROR(INDEX(M_User!$A$12:$J$67,MATCH(D10,M_User!$D$12:$D$67,0),3),"UNMAPPED") -> Joyline J Lyimo | H10: =IFERROR(INDEX(M_User!$A$12:$J$67,MATCH(D10,M_User!$D$12:$D$67,0),5),"UNMAPPED") -> MOS | I10: MOSFWH | J10: PH002 | K10: =IFERROR(INDEX(M_SKU!$A$18:$J$57,MATCH(J10,M_SKU!$B$18:$B$57,0),1),"UNKNOWN SKU") -> Sprite Pet 500ML (x 12) | L10: CK6-33362 | M10: 46158 | N10: 46269 | O10: 15 | P10: Pending Confirmation | U10: =D10 & "|" & J10 & "|" & L10 -> MOS100802|PH002|CK6-33362
A11: L-0001 | B11: 166147 | C11: 46179 | D11: MOS100802 | E11: Joyline J Lyimo | F11: =IFERROR(INDEX(M_User!$A$12:$J$67,MATCH(D11,M_User!$D$12:$D$67,0),1),"UNMAPPED") -> 45 | G11: =IFERROR(INDEX(M_User!$A$12:$J$67,MATCH(D11,M_User!$D$12:$D$67,0),3),"UNMAPPED") -> Joyline J Lyimo | H11: =IFERROR(INDEX(M_User!$A$12:$J$67,MATCH(D11,M_User!$D$12:$D$67,0),5),"UNMAPPED") -> MOS | I11: MOSFWH | J11: PH003 | K11: =IFERROR(INDEX(M_SKU!$A$18:$J$57,MATCH(J11,M_SKU!$B$18:$B$57,0),1),"UNKNOWN SKU") -> Fanta Orange Pet 500ML ( x 12) | L11: CK6-33405 | M11: 46172 | N11: 46283 | O11: 40 | P11: Pending Confirmation | U11: =D11 & "|" & J11 & "|" & L11 -> MOS100802|PH003|CK6-33405
A12: L-0001 | B12: 166147 | C12: 46179 | D12: MOS100802 | E12: Joyline J Lyimo | F12: =IFERROR(INDEX(M_User!$A$12:$J$67,MATCH(D12,M_User!$D$12:$D$67,0),1),"UNMAPPED") -> 45 | G12: =IFERROR(INDEX(M_User!$A$12:$J$67,MATCH(D12,M_User!$D$12:$D$67,0),3),"UNMAPPED") -> Joyline J Lyimo | H12: =IFERROR(INDEX(M_User!$A$12:$J$67,MATCH(D12,M_User!$D$12:$D$67,0),5),"UNMAPPED") -> MOS | I12: MOSFWH | J12: PH004 | K12: =IFERROR(INDEX(M_SKU!$A$18:$J$57,MATCH(J12,M_SKU!$B$18:$B$57,0),1),"UNKNOWN SKU") -> Fanta Passion Pet 500ML ( x12) | L12: CK5-33334 | M12: 46151 | N12: 46262 | O12: 15 | P12: Pending Confirmation | U12: =D12 & "|" & J12 & "|" & L12 -> MOS100802|PH004|CK5-33334
A13: L-0001 | B13: 166147 | C13: 46179 | D13: MOS100802 | E13: Joyline J Lyimo | F13: =IFERROR(INDEX(M_User!$A$12:$J$67,MATCH(D13,M_User!$D$12:$D$67,0),1),"UNMAPPED") -> 45 | G13: =IFERROR(INDEX(M_User!$A$12:$J$67,MATCH(D13,M_User!$D$12:$D$67,0),3),"UNMAPPED") -> Joyline J Lyimo | H13: =IFERROR(INDEX(M_User!$A$12:$J$67,MATCH(D13,M_User!$D$12:$D$67,0),5),"UNMAPPED") -> MOS | I13: MOSFWH | J13: PH007 | K13: =IFERROR(INDEX(M_SKU!$A$18:$J$57,MATCH(J13,M_SKU!$B$18:$B$57,0),1),"UNKNOWN SKU") -> Stoney Tangawizi Pet 500 ml ( x12) | L13: CK6-33375 | M13: 46161 | N13: 46272 | O13: 5 | P13: Pending Confirmation | U13: =D13 & "|" & J13 & "|" & L13 -> MOS100802|PH007|CK6-33375
A14: L-0001 | B14: 166147 | C14: 46179 | D14: MOS100802 | E14: Joyline J Lyimo | F14: =IFERROR(INDEX(M_User!$A$12:$J$67,MATCH(D14,M_User!$D$12:$D$67,0),1),"UNMAPPED") -> 45 | G14: =IFERROR(INDEX(M_User!$A$12:$J$67,MATCH(D14,M_User!$D$12:$D$67,0),3),"UNMAPPED") -> Joyline J Lyimo | H14: =IFERROR(INDEX(M_User!$A$12:$J$67,MATCH(D14,M_User!$D$12:$D$67,0),5),"UNMAPPED") -> MOS | I14: MOSFWH | J14: PH008 | K14: =IFERROR(INDEX(M_SKU!$A$18:$J$57,MATCH(J14,M_SKU!$B$18:$B$57,0),1),"UNKNOWN SKU") -> Sparletta Pinenut Pet 500 ml ( x12) | L14: CK5-33370 | M14: 46161 | N14: 46272 | O14: 5 | P14: Pending Confirmation | U14: =D14 & "|" & J14 & "|" & L14 -> MOS100802|PH008|CK5-33370
A15: L-0002 | B15: 166148 | C15: 46179 | D15: MOS100645 | E15: Riziki Rajabu | F15: =IFERROR(INDEX(M_User!$A$12:$J$67,MATCH(D15,M_User!$D$12:$D$67,0),1),"UNMAPPED") -> 50 | G15: =IFERROR(INDEX(M_User!$A$12:$J$67,MATCH(D15,M_User!$D$12:$D$67,0),3),"UNMAPPED") -> Riziki Rajabu Mghamba | H15: =IFERROR(INDEX(M_User!$A$12:$J$67,MATCH(D15,M_User!$D$12:$D$67,0),5),"UNMAPPED") -> MOS | I15: MOSFWH | J15: FG001 | K15: =IFERROR(INDEX(M_SKU!$A$18:$J$57,MATCH(J15,M_SKU!$B$18:$B$57,0),1),"UNKNOWN SKU") -> Coke RGB 350ml | L15: CK3-33408 | M15: 46175 | N15: 46539 | O15: 15.58 | P15: Pending Confirmation | U15: =D15 & "|" & J15 & "|" & L15 -> MOS100645|FG001|CK3-33408
A16: L-0002 | B16: 166148 | C16: 46179 | D16: MOS100645 | E16: Riziki Rajabu | F16: =IFERROR(INDEX(M_User!$A$12:$J$67,MATCH(D16,M_User!$D$12:$D$67,0),1),"UNMAPPED") -> 50 | G16: =IFERROR(INDEX(M_User!$A$12:$J$67,MATCH(D16,M_User!$D$12:$D$67,0),3),"UNMAPPED") -> Riziki Rajabu Mghamba | H16: =IFERROR(INDEX(M_User!$A$12:$J$67,MATCH(D16,M_User!$D$12:$D$67,0),5),"UNMAPPED") -> MOS | I16: MOSFWH | J16: FG001 | K16: =IFERROR(INDEX(M_SKU!$A$18:$J$57,MATCH(J16,M_SKU!$B$18:$B$57,0),1),"UNKNOWN SKU") -> Coke RGB 350ml | L16: CK3-33409 | M16: 46175 | N16: 46539 | O16: 64.42 | P16: Pending Confirmation | U16: =D16 & "|" & J16 & "|" & L16 -> MOS100645|FG001|CK3-33409
A17: L-0002 | B17: 166148 | C17: 46179 | D17: MOS100645 | E17: Riziki Rajabu | F17: =IFERROR(INDEX(M_User!$A$12:$J$67,MATCH(D17,M_User!$D$12:$D$67,0),1),"UNMAPPED") -> 50 | G17: =IFERROR(INDEX(M_User!$A$12:$J$67,MATCH(D17,M_User!$D$12:$D$67,0),3),"UNMAPPED") -> Riziki Rajabu Mghamba | H17: =IFERROR(INDEX(M_User!$A$12:$J$67,MATCH(D17,M_User!$D$12:$D$67,0),5),"UNMAPPED") -> MOS | I17: MOSFWH | J17: FG002 | K17: =IFERROR(INDEX(M_SKU!$A$18:$J$57,MATCH(J17,M_SKU!$B$18:$B$57,0),1),"UNKNOWN SKU") -> Fanta Orange RGB 350ml | L17: CK3-33407 | M17: 46174 | N17: 46538 | O17: 30 | P17: Pending Confirmation | U17: =D17 & "|" & J17 & "|" & L17 -> MOS100645|FG002|CK3-33407
A18: L-0002 | B18: 166148 | C18: 46179 | D18: MOS100645 | E18: Riziki Rajabu | F18: =IFERROR(INDEX(M_User!$A$12:$J$67,MATCH(D18,M_User!$D$12:$D$67,0),1),"UNMAPPED") -> 50 | G18: =IFERROR(INDEX(M_User!$A$12:$J$67,MATCH(D18,M_User!$D$12:$D$67,0),3),"UNMAPPED") -> Riziki Rajabu Mghamba | H18: =IFERROR(INDEX(M_User!$A$12:$J$67,MATCH(D18,M_User!$D$12:$D$67,0),5),"UNMAPPED") -> MOS | I18: MOSFWH | J18: FG003 | K18: =IFERROR(INDEX(M_SKU!$A$18:$J$57,MATCH(J18,M_SKU!$B$18:$B$57,0),1),"UNKNOWN SKU") -> Fanta Passion RGB 350ml | L18: CK3-33387 | M18: 46164 | N18: 46528 | O18: 15 | P18: Pending Confirmation | U18: =D18 & "|" & J18 & "|" & L18 -> MOS100645|FG003|CK3-33387
A19: L-0002 | B19: 166148 | C19: 46179 | D19: MOS100645 | E19: Riziki Rajabu | F19: =IFERROR(INDEX(M_User!$A$12:$J$67,MATCH(D19,M_User!$D$12:$D$67,0),1),"UNMAPPED") -> 50 | G19: =IFERROR(INDEX(M_User!$A$12:$J$67,MATCH(D19,M_User!$D$12:$D$67,0),3),"UNMAPPED") -> Riziki Rajabu Mghamba | H19: =IFERROR(INDEX(M_User!$A$12:$J$67,MATCH(D19,M_User!$D$12:$D$67,0),5),"UNMAPPED") -> MOS | I19: MOSFWH | J19: FG004 | K19: =IFERROR(INDEX(M_SKU!$A$18:$J$57,MATCH(J19,M_SKU!$B$18:$B$57,0),1),"UNKNOWN SKU") -> Fanta Pineapple RGB 350ml | L19: CK3-33385 | M19: 46163 | N19: 46527 | O19: 15 | P19: Pending Confirmation | U19: =D19 & "|" & J19 & "|" & L19 -> MOS100645|FG004|CK3-33385
A20: L-0002 | B20: 166148 | C20: 46179 | D20: MOS100645 | E20: Riziki Rajabu | F20: =IFERROR(INDEX(M_User!$A$12:$J$67,MATCH(D20,M_User!$D$12:$D$67,0),1),"UNMAPPED") -> 50 | G20: =IFERROR(INDEX(M_User!$A$12:$J$67,MATCH(D20,M_User!$D$12:$D$67,0),3),"UNMAPPED") -> Riziki Rajabu Mghamba | H20: =IFERROR(INDEX(M_User!$A$12:$J$67,MATCH(D20,M_User!$D$12:$D$67,0),5),"UNMAPPED") -> MOS | I20: MOSFWH | J20: FG005 | K20: =IFERROR(INDEX(M_SKU!$A$18:$J$57,MATCH(J20,M_SKU!$B$18:$B$57,0),1),"UNKNOWN SKU") -> Fanta Fruit Blast RGB 350 ml | L20: CK3-33402 | M20: 46171 | N20: 46535 | O20: 12 | P20: Pending Confirmation | U20: =D20 & "|" & J20 & "|" & L20 -> MOS100645|FG005|CK3-33402
... A439: L-0020 | B439: 4078166 | C439: 46179 | D439: DSM300140 | E439: Omary seif | F439: =IFERROR(INDEX(M_User!$A$12:$J$67,MATCH(D439,M_User!$D$12:$D$67,0),1),"UNMAPPED") -> 89 | G439: =IFERROR(INDEX(M_User!$A$12:$J$67,MATCH(D439,M_User!$D$12:$D$67,0),3),"UNMAPPED") -> Omary O. Seif | H439: =IFERROR(INDEX(M_User!$A$12:$J$67,MATCH(D439,M_User!$D$12:$D$67,0),5),"UNMAPPED") -> DAR | I439: DSMFWH | J439: KD007 | K439: =IFERROR(INDEX(M_SKU!$A$18:$J$57,MATCH(J439,M_SKU!$B$18:$B$57,0),1),"UNKNOWN SKU") -> KNMW 1000ml(6 Pack) | L439: CK4-833 | M439: 46167 | N439: 46531 | O439: 300 | P439: Pending Confirmation | U439: =D439 & "|" & J439 & "|" & L439 -> DSM300140|KD007|CK4-833
A442: SUMMARY
A443: Total Load Rows: | B443: =COUNTA(A9:A439) -> 431
A444: Unique Invoices: | B444: =SUMPRODUCT(1/COUNTIF(B9:B439,B9:B439)) -> 20
A445: Unique Salesmen (SAP): | B445: =SUMPRODUCT(1/COUNTIF(D9:D439,D9:D439)) -> 18
A446: Unmapped Rows (Force-Push needed): | B446: =COUNTIF(F9:F439,"UNMAPPED") -> 24
A448: Status Breakdown:
A449: Pending Confirmation: | B449: =COUNTIF(P9:P439,"Pending Confirmation") -> 431
A450: Confirmed: | B450: =COUNTIF(P9:P439,"Confirmed") -> 0
A451: Force-Pushed: | B451: =COUNTIF(P9:P439,"Force-Pushed") -> 0
A452: Rejected: | B452: =COUNTIF(P9:P439,"Rejected") -> 0
A454: Data Integrity Checks
A455: Unique Stock Keys (rows): | B455: =SUMPRODUCT(1/COUNTIF(U9:U439,U9:U439)) -> 424
A456: Rows with UNKNOWN SKU: | B456: =COUNTIF(K9:K439,"UNKNOWN SKU") -> 0
A457: Total Quantity Across All Loads: | B457: =SUM(O9:O439) -> 8286

Sheet T_Sales
A1: T_Sales — Mobile Sales Recorded by Salesmen
A2: Every sale recorded on a salesman's mobile app. Each row = one outlet visit + one SKU+Batch line.
A3: IMPORTANT: Sales records are IMMUTABLE. They cannot be modified after entry. Variance resolution flows around this constraint.
A4: Used downstream to compute Expected ROP = Load − Sales (per Salesman × SKU × Batch).
A6: Column Groups: | B6: Identification | D6: Mobile-Entered | F6: Resolved by SFA | H6: Pricing (Cascade) | J6: Derived Key
A8: Sale ID | B8: Load ID | C8: Sale Date | D8: Salesman SAP Code | E8: Salesman Name | F8: Salesman Depot | G8: Outlet Code | H8: Outlet Name | I8: SKU Code | J8: SKU Name | K8: Batch Number | L8: Quantity (Units) | M8: Unit Price (TZS) | N8: Sale Value (TZS) | O8: Stock Key
A9: S-00084 | B9: L-0019 | C9: 46179 | D9: ARS000069 | E9: =IFERROR(INDEX(M_User!$A$12:$J$67,MATCH(D9,M_User!$D$12:$D$67,0),3),"UNMAPPED") -> Doglas E. Shirima | F9: =IFERROR(INDEX(M_User!$A$12:$J$67,MATCH(D9,M_User!$D$12:$D$67,0),5),"UNMAPPED") -> ARS | G9: OUT-ARS-001 | H9: Sokoine Road Stores | I9: FG001 | J9: =IFERROR(INDEX(M_SKU!$A$18:$J$57,MATCH(I9,M_SKU!$B$18:$B$57,0),1),"UNKNOWN SKU") -> Coke RGB 350ml | K9: CK3-33379 | L9: 4.4610496 | M9: {=IFERROR(INDEX(M_DepotPrice!$C$10:$C$52,MATCH(1,(M_DepotPrice!$A$10:$A$52=I9)*(M_DepotPrice!$H$10:$H$52=IFERROR(INDEX(M_Depot!$A$7:$A$24,MATCH(F9,M_Depot!$B$7:$B$24,0)),""))*(M_DepotPrice!$G$10:$G$52="Special"),0)),INDEX(M_DepotPrice!$C$10:$C$52,MATCH(1,(M_DepotPrice!$A$10:$A$52=I9)*(M_DepotPrice!$G$10:$G$52="Default"),0)))} -> 11780 | N9: =(L9*M9)*1.18 -> 62010.374 | O9: =D9 & "|" & I9 & "|" & K9 -> ARS000069|FG001|CK3-33379 | P9: =ROUND(M9*1.18*L9,0) -> 62010
A10: S-00013 | B10: L-0019 | C10: 46179 | D10: ARS000069 | E10: =IFERROR(INDEX(M_User!$A$12:$J$67,MATCH(D10,M_User!$D$12:$D$67,0),3),"UNMAPPED") -> Doglas E. Shirima | F10: =IFERROR(INDEX(M_User!$A$12:$J$67,MATCH(D10,M_User!$D$12:$D$67,0),5),"UNMAPPED") -> ARS | G10: OUT-ARS-001 | H10: Sokoine Road Stores | I10: FG003 | J10: =IFERROR(INDEX(M_SKU!$A$18:$J$57,MATCH(I10,M_SKU!$B$18:$B$57,0),1),"UNKNOWN SKU") -> Fanta Passion RGB 350ml | K10: CK3-33290 | L10: 0.61213082 | M10: {=IFERROR(INDEX(M_DepotPrice!$C$10:$C$52,MATCH(1,(M_DepotPrice!$A$10:$A$52=I10)*(M_DepotPrice!$H$10:$H$52=IFERROR(INDEX(M_Depot!$A$7:$A$24,MATCH(F10,M_Depot!$B$7:$B$24,0)),""))*(M_DepotPrice!$G$10:$G$52="Special"),0)),INDEX(M_DepotPrice!$C$10:$C$52,MATCH(1,(M_DepotPrice!$A$10:$A$52=I10)*(M_DepotPrice!$G$10:$G$52="Default"),0)))} -> 11780 | N10: =(L10*M10)*1.18 -> 8508.8632 | O10: =D10 & "|" & I10 & "|" & K10 -> ARS000069|FG003|CK3-33290
A11: S-00015 | B11: L-0019 | C11: 46179 | D11: ARS000069 | E11: =IFERROR(INDEX(M_User!$A$12:$J$67,MATCH(D11,M_User!$D$12:$D$67,0),3),"UNMAPPED") -> Doglas E. Shirima | F11: =IFERROR(INDEX(M_User!$A$12:$J$67,MATCH(D11,M_User!$D$12:$D$67,0),5),"UNMAPPED") -> ARS | G11: OUT-ARS-001 | H11: Sokoine Road Stores | I11: FG004 | J11: =IFERROR(INDEX(M_SKU!$A$18:$J$57,MATCH(I11,M_SKU!$B$18:$B$57,0),1),"UNKNOWN SKU") -> Fanta Pineapple RGB 350ml | K11: CK5-33354 | L11: 0.46663565 | M11: {=IFERROR(INDEX(M_DepotPrice!$C$10:$C$52,MATCH(1,(M_DepotPrice!$A$10:$A$52=I11)*(M_DepotPrice!$H$10:$H$52=IFERROR(INDEX(M_Depot!$A$7:$A$24,MATCH(F11,M_Depot!$B$7:$B$24,0)),""))*(M_DepotPrice!$G$10:$G$52="Special"),0)),INDEX(M_DepotPrice!$C$10:$C$52,MATCH(1,(M_DepotPrice!$A$10:$A$52=I11)*(M_DepotPrice!$G$10:$G$52="Default"),0)))} -> 11780 | N11: =(L11*M11)*1.18 -> 6486.4222 | O11: =D11 & "|" & I11 & "|" & K11 -> ARS000069|FG004|CK5-33354
A12: S-00016 | B12: L-0019 | C12: 46179 | D12: ARS000069 | E12: =IFERROR(INDEX(M_User!$A$12:$J$67,MATCH(D12,M_User!$D$12:$D$67,0),3),"UNMAPPED") -> Doglas E. Shirima | F12: =IFERROR(INDEX(M_User!$A$12:$J$67,MATCH(D12,M_User!$D$12:$D$67,0),5),"UNMAPPED") -> ARS | G12: OUT-ARS-001 | H12: Sokoine Road Stores | I12: FG006 | J12: =IFERROR(INDEX(M_SKU!$A$18:$J$57,MATCH(I12,M_SKU!$B$18:$B$57,0),1),"UNKNOWN SKU") -> Sprite 350ml | K12: CK3-33306 | L12: 0.2439 | M12: {=IFERROR(INDEX(M_DepotPrice!$C$10:$C$52,MATCH(1,(M_DepotPrice!$A$10:$A$52=I12)*(M_DepotPrice!$H$10:$H$52=IFERROR(INDEX(M_Depot!$A$7:$A$24,MATCH(F12,M_Depot!$B$7:$B$24,0)),""))*(M_DepotPrice!$G$10:$G$52="Special"),0)),INDEX(M_DepotPrice!$C$10:$C$52,MATCH(1,(M_DepotPrice!$A$10:$A$52=I12)*(M_DepotPrice!$G$10:$G$52="Default"),0)))} -> 11780 | N12: =(L12*M12)*1.18 -> 3390.3076 | O12: =D12 & "|" & I12 & "|" & K12 -> ARS000069|FG006|CK3-33306
A13: S-00022 | B13: L-0019 | C13: 46179 | D13: ARS000069 | E13: =IFERROR(INDEX(M_User!$A$12:$J$67,MATCH(D13,M_User!$D$12:$D$67,0),3),"UNMAPPED") -> Doglas E. Shirima | F13: =IFERROR(INDEX(M_User!$A$12:$J$67,MATCH(D13,M_User!$D$12:$D$67,0),5),"UNMAPPED") -> ARS | G13: OUT-ARS-001 | H13: Sokoine Road Stores | I13: FG009 | J13: =IFERROR(INDEX(M_SKU!$A$18:$J$57,MATCH(I13,M_SKU!$B$18:$B$57,0),1),"UNKNOWN SKU") -> Krest Bitter Lemon RGB 300ml | K13: CK3-33348 | L13: 1.2692724 | M13: {=IFERROR(INDEX(M_DepotPrice!$C$10:$C$52,MATCH(1,(M_DepotPrice!$A$10:$A$52=I13)*(M_DepotPrice!$H$10:$H$52=IFERROR(INDEX(M_Depot!$A$7:$A$24,MATCH(F13,M_Depot!$B$7:$B$24,0)),""))*(M_DepotPrice!$G$10:$G$52="Special"),0)),INDEX(M_DepotPrice!$C$10:$C$52,MATCH(1,(M_DepotPrice!$A$10:$A$52=I13)*(M_DepotPrice!$G$10:$G$52="Default"),0)))} -> 11780 | N13: =(L13*M13)*1.18 -> 17643.394 | O13: =D13 & "|" & I13 & "|" & K13 -> ARS000069|FG009|CK3-33348
A14: S-00026 | B14: L-0019 | C14: 46179 | D14: ARS000069 | E14: =IFERROR(INDEX(M_User!$A$12:$J$67,MATCH(D14,M_User!$D$12:$D$67,0),3),"UNMAPPED") -> Doglas E. Shirima | F14: =IFERROR(INDEX(M_User!$A$12:$J$67,MATCH(D14,M_User!$D$12:$D$67,0),5),"UNMAPPED") -> ARS | G14: OUT-ARS-001 | H14: Sokoine Road Stores | I14: FG010 | J14: =IFERROR(INDEX(M_SKU!$A$18:$J$57,MATCH(I14,M_SKU!$B$18:$B$57,0),1),"UNKNOWN SKU") -> Krest Club Soda RGB 300ml | K14: CK3-33301 | L14: 0.92523012 | M14: {=IFERROR(INDEX(M_DepotPrice!$C$10:$C$52,MATCH(1,(M_DepotPrice!$A$10:$A$52=I14)*(M_DepotPrice!$H$10:$H$52=IFERROR(INDEX(M_Depot!$A$7:$A$24,MATCH(F14,M_Depot!$B$7:$B$24,0)),""))*(M_DepotPrice!$G$10:$G$52="Special"),0)),INDEX(M_DepotPrice!$C$10:$C$52,MATCH(1,(M_DepotPrice!$A$10:$A$52=I14)*(M_DepotPrice!$G$10:$G$52="Default"),0)))} -> 11780 | N14: =(L14*M14)*1.18 -> 12861.069 | O14: =D14 & "|" & I14 & "|" & K14 -> ARS000069|FG010|CK3-33301
A15: S-00029 | B15: L-0019 | C15: 46179 | D15: ARS000069 | E15: =IFERROR(INDEX(M_User!$A$12:$J$67,MATCH(D15,M_User!$D$12:$D$67,0),3),"UNMAPPED") -> Doglas E. Shirima | F15: =IFERROR(INDEX(M_User!$A$12:$J$67,MATCH(D15,M_User!$D$12:$D$67,0),5),"UNMAPPED") -> ARS | G15: OUT-ARS-001 | H15: Sokoine Road Stores | I15: FG011 | J15: =IFERROR(INDEX(M_SKU!$A$18:$J$57,MATCH(I15,M_SKU!$B$18:$B$57,0),1),"UNKNOWN SKU") -> Krest Tonic Water RGB 300ml | K15: CK3-33237 | L15: 0.6615 | M15: {=IFERROR(INDEX(M_DepotPrice!$C$10:$C$52,MATCH(1,(M_DepotPrice!$A$10:$A$52=I15)*(M_DepotPrice!$H$10:$H$52=IFERROR(INDEX(M_Depot!$A$7:$A$24,MATCH(F15,M_Depot!$B$7:$B$24,0)),""))*(M_DepotPrice!$G$10:$G$52="Special"),0)),INDEX(M_DepotPrice!$C$10:$C$52,MATCH(1,(M_DepotPrice!$A$10:$A$52=I15)*(M_DepotPrice!$G$10:$G$52="Default"),0)))} -> 11780 | N15: =(L15*M15)*1.18 -> 9195.1146 | O15: =D15 & "|" & I15 & "|" & K15 -> ARS000069|FG011|CK3-33237
A16: S-00032 | B16: L-0019 | C16: 46179 | D16: ARS000069 | E16: =IFERROR(INDEX(M_User!$A$12:$J$67,MATCH(D16,M_User!$D$12:$D$67,0),3),"UNMAPPED") -> Doglas E. Shirima | F16: =IFERROR(INDEX(M_User!$A$12:$J$67,MATCH(D16,M_User!$D$12:$D$67,0),5),"UNMAPPED") -> ARS | G16: OUT-ARS-001 | H16: Sokoine Road Stores | I16: FG012 | J16: =IFERROR(INDEX(M_SKU!$A$18:$J$57,MATCH(I16,M_SKU!$B$18:$B$57,0),1),"UNKNOWN SKU") -> Krest Ginger Ale RGB 300ml | K16: CK3-33126 | L16: 0.2456 | M16: {=IFERROR(INDEX(M_DepotPrice!$C$10:$C$52,MATCH(1,(M_DepotPrice!$A$10:$A$52=I16)*(M_DepotPrice!$H$10:$H$52=IFERROR(INDEX(M_Depot!$A$7:$A$24,MATCH(F16,M_Depot!$B$7:$B$24,0)),""))*(M_DepotPrice!$G$10:$G$52="Special"),0)),INDEX(M_DepotPrice!$C$10:$C$52,MATCH(1,(M_DepotPrice!$A$10:$A$52=I16)*(M_DepotPrice!$G$10:$G$52="Default"),0)))} -> 11780 | N16: =(L16*M16)*1.18 -> 3413.9382 | O16: =D16 & "|" & I16 & "|" & K16 -> ARS000069|FG012|CK3-33126
A17: S-00035 | B17: L-0019 | C17: 46179 | D17: ARS000069 | E17: =IFERROR(INDEX(M_User!$A$12:$J$67,MATCH(D17,M_User!$D$12:$D$67,0),3),"UNMAPPED") -> Doglas E. Shirima | F17: =IFERROR(INDEX(M_User!$A$12:$J$67,MATCH(D17,M_User!$D$12:$D$67,0),5),"UNMAPPED") -> ARS | G17: OUT-ARS-001 | H17: Sokoine Road Stores | I17: KD001 | J17: =IFERROR(INDEX(M_SKU!$A$18:$J$57,MATCH(I17,M_SKU!$B$18:$B$57,0),1),"UNKNOWN SKU") -> KNMW 500ml | K17: CK4-836 | L17: 65 | M17: {=IFERROR(INDEX(M_DepotPrice!$C$10:$C$52,MATCH(1,(M_DepotPrice!$A$10:$A$52=I17)*(M_DepotPrice!$H$10:$H$52=IFERROR(INDEX(M_Depot!$A$7:$A$24,MATCH(F17,M_Depot!$B$7:$B$24,0)),""))*(M_DepotPrice!$G$10:$G$52="Special"),0)),INDEX(M_DepotPrice!$C$10:$C$52,MATCH(1,(M_DepotPrice!$A$10:$A$52=I17)*(M_DepotPrice!$G$10:$G$52="Default"),0)))} -> 3559 | N17: =(L17*M17)*1.18 -> 272975.3 | O17: =D17 & "|" & I17 & "|" & K17 -> ARS000069|KD001|CK4-836
A18: S-00036 | B18: L-0019 | C18: 46179 | D18: ARS000069 | E18: =IFERROR(INDEX(M_User!$A$12:$J$67,MATCH(D18,M_User!$D$12:$D$67,0),3),"UNMAPPED") -> Doglas E. Shirima | F18: =IFERROR(INDEX(M_User!$A$12:$J$67,MATCH(D18,M_User!$D$12:$D$67,0),5),"UNMAPPED") -> ARS | G18: OUT-ARS-001 | H18: Sokoine Road Stores | I18: KD001 | J18: =IFERROR(INDEX(M_SKU!$A$18:$J$57,MATCH(I18,M_SKU!$B$18:$B$57,0),1),"UNKNOWN SKU") -> KNMW 500ml | K18: CK6-983 | L18: 1 | M18: {=IFERROR(INDEX(M_DepotPrice!$C$10:$C$52,MATCH(1,(M_DepotPrice!$A$10:$A$52=I18)*(M_DepotPrice!$H$10:$H$52=IFERROR(INDEX(M_Depot!$A$7:$A$24,MATCH(F18,M_Depot!$B$7:$B$24,0)),""))*(M_DepotPrice!$G$10:$G$52="Special"),0)),INDEX(M_DepotPrice!$C$10:$C$52,MATCH(1,(M_DepotPrice!$A$10:$A$52=I18)*(M_DepotPrice!$G$10:$G$52="Default"),0)))} -> 3559 | N18: =(L18*M18)*1.18 -> 4199.62 | O18: =D18 & "|" & I18 & "|" & K18 -> ARS000069|KD001|CK6-983
A19: S-00053 | B19: L-0019 | C19: 46179 | D19: ARS000069 | E19: =IFERROR(INDEX(M_User!$A$12:$J$67,MATCH(D19,M_User!$D$12:$D$67,0),3),"UNMAPPED") -> Doglas E. Shirima | F19: =IFERROR(INDEX(M_User!$A$12:$J$67,MATCH(D19,M_User!$D$12:$D$67,0),5),"UNMAPPED") -> ARS | G19: OUT-ARS-001 | H19: Sokoine Road Stores | I19: KD004 | J19: =IFERROR(INDEX(M_SKU!$A$18:$J$57,MATCH(I19,M_SKU!$B$18:$B$57,0),1),"UNKNOWN SKU") -> Kilimanjaro Drinking Water 6000 ML | K19: CK7-895 | L19: 5 | M19: {=IFERROR(INDEX(M_DepotPrice!$C$10:$C$52,MATCH(1,(M_DepotPrice!$A$10:$A$52=I19)*(M_DepotPrice!$H$10:$H$52=IFERROR(INDEX(M_Depot!$A$7:$A$24,MATCH(F19,M_Depot!$B$7:$B$24,0)),""))*(M_DepotPrice!$G$10:$G$52="Special"),0)),INDEX(M_DepotPrice!$C$10:$C$52,MATCH(1,(M_DepotPrice!$A$10:$A$52=I19)*(M_DepotPrice!$G$10:$G$52="Default"),0)))} -> 2119 | N19: =(L19*M19)*1.18 -> 12502.1 | O19: =D19 & "|" & I19 & "|" & K19 -> ARS000069|KD004|CK7-895
A20: S-00058 | B20: L-0019 | C20: 46179 | D20: ARS000069 | E20: =IFERROR(INDEX(M_User!$A$12:$J$67,MATCH(D20,M_User!$D$12:$D$67,0),3),"UNMAPPED") -> Doglas E. Shirima | F20: =IFERROR(INDEX(M_User!$A$12:$J$67,MATCH(D20,M_User!$D$12:$D$67,0),5),"UNMAPPED") -> ARS | G20: OUT-ARS-001 | H20: Sokoine Road Stores | I20: KD005 | J20: =IFERROR(INDEX(M_SKU!$A$18:$J$57,MATCH(I20,M_SKU!$B$18:$B$57,0),1),"UNKNOWN SKU") -> Kilimanjaro Drinking Water 12000 ML | K20: CK7-909 | L20: 1 | M20: {=IFERROR(INDEX(M_DepotPrice!$C$10:$C$52,MATCH(1,(M_DepotPrice!$A$10:$A$52=I20)*(M_DepotPrice!$H$10:$H$52=IFERROR(INDEX(M_Depot!$A$7:$A$24,MATCH(F20,M_Depot!$B$7:$B$24,0)),""))*(M_DepotPrice!$G$10:$G$52="Special"),0)),INDEX(M_DepotPrice!$C$10:$C$52,MATCH(1,(M_DepotPrice!$A$10:$A$52=I20)*(M_DepotPrice!$G$10:$G$52="Default"),0)))} -> 3559 | N20: =(L20*M20)*1.18 -> 4199.62 | O20: =D20 & "|" & I20 & "|" & K20 -> ARS000069|KD005|CK7-909
A21: S-00063 | B21: L-0019 | C21: 46179 | D21: ARS000069 | E21: =IFERROR(INDEX(M_User!$A$12:$J$67,MATCH(D21,M_User!$D$12:$D$67,0),3),"UNMAPPED") -> Doglas E. Shirima | F21: =IFERROR(INDEX(M_User!$A$12:$J$67,MATCH(D21,M_User!$D$12:$D$67,0),5),"UNMAPPED") -> ARS | G21: OUT-ARS-001 | H21: Sokoine Road Stores | I21: KD006 | J21: =IFERROR(INDEX(M_SKU!$A$18:$J$57,MATCH(I21,M_SKU!$B$18:$B$57,0),1),"UNKNOWN SKU") -> Kilimanjaro Drinking Water 18900 ML | K21: CK7-914 | L21: 1 | M21: {=IFERROR(INDEX(M_DepotPrice!$C$10:$C$52,MATCH(1,(M_DepotPrice!$A$10:$A$52=I21)*(M_DepotPrice!$H$10:$H$52=IFERROR(INDEX(M_Depot!$A$7:$A$24,MATCH(F21,M_Depot!$B$7:$B$24,0)),""))*(M_DepotPrice!$G$10:$G$52="Special"),0)),INDEX(M_DepotPrice!$C$10:$C$52,MATCH(1,(M_DepotPrice!$A$10:$A$52=I21)*(M_DepotPrice!$G$10:$G$52="Default"),0)))} -> 5932 | N21: =(L21*M21)*1.18 -> 6999.76 | O21: =D21 & "|" & I21 & "|" & K21 -> ARS000069|KD006|CK7-914
... A1164: S-00092 | B1164: L-0020 | C1164: 46183 | D1164: DSM300140 | E1164: =IFERROR(INDEX(M_User!$A$12:$J$67,MATCH(D1164,M_User!$D$12:$D$67,0),3),"UNMAPPED") -> Omary O. Seif | F1164: =IFERROR(INDEX(M_User!$A$12:$J$67,MATCH(D1164,M_User!$D$12:$D$67,0),5),"UNMAPPED") -> DAR | G1164: OUT-DAR-007 | H1164: Mwananyamala Beverages | I1164: KD003 | J1164: =IFERROR(INDEX(M_SKU!$A$18:$J$57,MATCH(I1164,M_SKU!$B$18:$B$57,0),1),"UNKNOWN SKU") -> KNMW 1500ml | K1164: CK4-823 | L1164: 19 | M1164: {=IFERROR(INDEX(M_DepotPrice!$C$10:$C$52,MATCH(1,(M_DepotPrice!$A$10:$A$52=I1164)*(M_DepotPrice!$H$10:$H$52=IFERROR(INDEX(M_Depot!$A$7:$A$24,MATCH(F1164,M_Depot!$B$7:$B$24,0)),""))*(M_DepotPrice!$G$10:$G$52="Special"),0)),INDEX(M_DepotPrice!$C$10:$C$52,MATCH(1,(M_DepotPrice!$A$10:$A$52=I1164)*(M_DepotPrice!$G$10:$G$52="Default"),0)))} -> 3559 | N1164: =(L1164*M1164)*1.18 -> 79792.78 | O1164: =D1164 & "|" & I1164 & "|" & K1164 -> DSM300140|KD003|CK4-823
A1167: SUMMARY
A1168: Total Sale Rows: | B1168: =COUNTA(A9:A1164) -> 1156
A1169: Unique Salesmen: | B1169: =SUMPRODUCT(1/COUNTIF(D9:D1164,D9:D1164)) -> 17
A1170: Unique Outlets Visited: | B1170: =SUMPRODUCT(1/COUNTIF(G9:G1164,G9:G1164)) -> 20
A1171: Total Quantity Sold: | B1171: =SUM(L9:L1164) -> 6616.9405
A1172: Total Sale Value (TZS): | B1172: =SUM(N9:N1164) -> 55971817
A1174: Scenario Distribution (designed):
A1175: Clean matches: | B1175: 13 salesmen
A1176: Shortage (Default Outlet posting): | B1176: 1 salesman — Riziki Rajabu (MOS100645)
A1177: Excess (Unload adjustment): | B1177: 1 salesman — Joyline J Lyimo (MOS100802)
A1178: Safari sales (multi-day): | B1178: 1 salesman — Omary O. Seif (DSM300140)
A1179: Sub-unit / decimal sales: | B1179: 1 salesman — Doglas E. Shirima (ARS000069)
A1180: No sales (Force-Push pending): | B1180: James Tegemea Ndosi (MOS100801)

Sheet T_Unload
A1: T_Unload — Mobile Unload (Auto-Derived)
A2: Auto-derived from T_Load and T_Sales. Each row = one unique Stock Key (Salesman + SKU + Batch).
A3: Expected ROP = Sum of Load Qty − Sum of Sales Qty (per Stock Key). This is what the system EXPECTS to be in the van.
A4: In the live system: salesman clicks "Unload" on his mobile; quantities flow automatically. He cannot manipulate these numbers.
A5: Next step (T_ROP): Clerk enters Actual ROP at the depot. Variance = Expected ROP − Actual ROP.
A7: Column Groups: | B7: Identification | D7: Resolved by SFA | F7: Computed | H7: State | J7: Derived Key
A9: Unload ID | B9: Stock Key | C9: Salesman SAP Code | D9: Salesman Name | E9: Depot | F9: SKU Code | G9: SKU Name | H9: Batch Number | I9: Load Qty (Sum) | J9: Sales Qty (Sum) | K9: Expected ROP | L9: Unload Date | M9: Unload Status
A10: U-0001 | B10: ARS000069|FG001|CK3-33379 | C10: ARS000069 | D10: =IFERROR(INDEX(M_User!$A$12:$J$67,MATCH(C10,M_User!$D$12:$D$67,0),3),"UNMAPPED") -> Doglas E. Shirima | E10: =IFERROR(INDEX(M_User!$A$12:$J$67,MATCH(C10,M_User!$D$12:$D$67,0),5),"UNMAPPED") -> ARS | F10: FG001 | G10: =IFERROR(INDEX(M_SKU!$A$18:$J$57,MATCH(F10,M_SKU!$B$18:$B$57,0),1),"UNKNOWN SKU") -> Coke RGB 350ml | H10: CK3-33379 | I10: =SUMIF(T_Load!$U$9:$U$439,B10,T_Load!$O$9:$O$439) -> 15 | J10: =SUMIF(T_Sales!$O$9:$O$1164,B10,T_Sales!$L$9:$L$1164) -> 12.43255 | K10: =I10-J10 -> 2.5674504 | L10: 46179 | M10: Pending Unload
A11: U-0002 | B11: ARS000069|FG002|CK3-33372 | C11: ARS000069 | D11: =IFERROR(INDEX(M_User!$A$12:$J$67,MATCH(C11,M_User!$D$12:$D$67,0),3),"UNMAPPED") -> Doglas E. Shirima | E11: =IFERROR(INDEX(M_User!$A$12:$J$67,MATCH(C11,M_User!$D$12:$D$67,0),5),"UNMAPPED") -> ARS | F11: FG002 | G11: =IFERROR(INDEX(M_SKU!$A$18:$J$57,MATCH(F11,M_SKU!$B$18:$B$57,0),1),"UNKNOWN SKU") -> Fanta Orange RGB 350ml | H11: CK3-33372 | I11: =SUMIF(T_Load!$U$9:$U$439,B11,T_Load!$O$9:$O$439) -> 5 | J11: =SUMIF(T_Sales!$O$9:$O$1164,B11,T_Sales!$L$9:$L$1164) -> 3.9835374 | K11: =I11-J11 -> 1.0164626 | L11: 46179 | M11: Pending Unload
A12: U-0003 | B12: ARS000069|FG003|CK3-33290 | C12: ARS000069 | D12: =IFERROR(INDEX(M_User!$A$12:$J$67,MATCH(C12,M_User!$D$12:$D$67,0),3),"UNMAPPED") -> Doglas E. Shirima | E12: =IFERROR(INDEX(M_User!$A$12:$J$67,MATCH(C12,M_User!$D$12:$D$67,0),5),"UNMAPPED") -> ARS | F12: FG003 | G12: =IFERROR(INDEX(M_SKU!$A$18:$J$57,MATCH(F12,M_SKU!$B$18:$B$57,0),1),"UNKNOWN SKU") -> Fanta Passion RGB 350ml | H12: CK3-33290 | I12: =SUMIF(T_Load!$U$9:$U$439,B12,T_Load!$O$9:$O$439) -> 2 | J12: =SUMIF(T_Sales!$O$9:$O$1164,B12,T_Sales!$L$9:$L$1164) -> 1.5189308 | K12: =I12-J12 -> 0.48106918 | L12: 46179 | M12: Pending Unload
A13: U-0004 | B13: ARS000069|FG004|CK5-33354 | C13: ARS000069 | D13: =IFERROR(INDEX(M_User!$A$12:$J$67,MATCH(C13,M_User!$D$12:$D$67,0),3),"UNMAPPED") -> Doglas E. Shirima | E13: =IFERROR(INDEX(M_User!$A$12:$J$67,MATCH(C13,M_User!$D$12:$D$67,0),5),"UNMAPPED") -> ARS | F13: FG004 | G13: =IFERROR(INDEX(M_SKU!$A$18:$J$57,MATCH(F13,M_SKU!$B$18:$B$57,0),1),"UNKNOWN SKU") -> Fanta Pineapple RGB 350ml | H13: CK5-33354 | I13: =SUMIF(T_Load!$U$9:$U$439,B13,T_Load!$O$9:$O$439) -> 2 | J13: =SUMIF(T_Sales!$O$9:$O$1164,B13,T_Sales!$L$9:$L$1164) -> 1.4224357 | K13: =I13-J13 -> 0.57756435 | L13: 46179 | M13: Pending Unload
A14: U-0005 | B14: ARS000069|FG006|CK3-33306 | C14: ARS000069 | D14: =IFERROR(INDEX(M_User!$A$12:$J$67,MATCH(C14,M_User!$D$12:$D$67,0),3),"UNMAPPED") -> Doglas E. Shirima | E14: =IFERROR(INDEX(M_User!$A$12:$J$67,MATCH(C14,M_User!$D$12:$D$67,0),5),"UNMAPPED") -> ARS | F14: FG006 | G14: =IFERROR(INDEX(M_SKU!$A$18:$J$57,MATCH(F14,M_SKU!$B$18:$B$57,0),1),"UNKNOWN SKU") -> Sprite 350ml | H14: CK3-33306 | I14: =SUMIF(T_Load!$U$9:$U$439,B14,T_Load!$O$9:$O$439) -> 2 | J14: =SUMIF(T_Sales!$O$9:$O$1164,B14,T_Sales!$L$9:$L$1164) -> 1.5417 | K14: =I14-J14 -> 0.4583 | L14: 46179 | M14: Pending Unload
A15: U-0006 | B15: ARS000069|FG009|CK3-33348 | C15: ARS000069 | D15: =IFERROR(INDEX(M_User!$A$12:$J$67,MATCH(C15,M_User!$D$12:$D$67,0),3),"UNMAPPED") -> Doglas E. Shirima | E15: =IFERROR(INDEX(M_User!$A$12:$J$67,MATCH(C15,M_User!$D$12:$D$67,0),5),"UNMAPPED") -> ARS | F15: FG009 | G15: =IFERROR(INDEX(M_SKU!$A$18:$J$57,MATCH(F15,M_SKU!$B$18:$B$57,0),1),"UNKNOWN SKU") -> Krest Bitter Lemon RGB 300ml | H15: CK3-33348 | I15: =SUMIF(T_Load!$U$9:$U$439,B15,T_Load!$O$9:$O$439) -> 3 | J15: =SUMIF(T_Sales!$O$9:$O$1164,B15,T_Sales!$L$9:$L$1164) -> 2.4120724 | K15: =I15-J15 -> 0.58792761 | L15: 46179 | M15: Pending Unload
A16: U-0007 | B16: ARS000069|FG010|CK3-33301 | C16: ARS000069 | D16: =IFERROR(INDEX(M_User!$A$12:$J$67,MATCH(C16,M_User!$D$12:$D$67,0),3),"UNMAPPED") -> Doglas E. Shirima | E16: =IFERROR(INDEX(M_User!$A$12:$J$67,MATCH(C16,M_User!$D$12:$D$67,0),5),"UNMAPPED") -> ARS | F16: FG010 | G16: =IFERROR(INDEX(M_SKU!$A$18:$J$57,MATCH(F16,M_SKU!$B$18:$B$57,0),1),"UNKNOWN SKU") -> Krest Club Soda RGB 300ml | H16: CK3-33301 | I16: =SUMIF(T_Load!$U$9:$U$439,B16,T_Load!$O$9:$O$439) -> 3 | J16: =SUMIF(T_Sales!$O$9:$O$1164,B16,T_Sales!$L$9:$L$1164) -> 2.2570301 | K16: =I16-J16 -> 0.74296988 | L16: 46179 | M16: Pending Unload
A17: U-0008 | B17: ARS000069|FG011|CK3-33237 | C17: ARS000069 | D17: =IFERROR(INDEX(M_User!$A$12:$J$67,MATCH(C17,M_User!$D$12:$D$67,0),3),"UNMAPPED") -> Doglas E. Shirima | E17: =IFERROR(INDEX(M_User!$A$12:$J$67,MATCH(C17,M_User!$D$12:$D$67,0),5),"UNMAPPED") -> ARS | F17: FG011 | G17: =IFERROR(INDEX(M_SKU!$A$18:$J$57,MATCH(F17,M_SKU!$B$18:$B$57,0),1),"UNKNOWN SKU") -> Krest Tonic Water RGB 300ml | H17: CK3-33237 | I17: =SUMIF(T_Load!$U$9:$U$439,B17,T_Load!$O$9:$O$439) -> 3 | J17: =SUMIF(T_Sales!$O$9:$O$1164,B17,T_Sales!$L$9:$L$1164) -> 2.3133117 | K17: =I17-J17 -> 0.68668833 | L17: 46179 | M17: Pending Unload
A18: U-0009 | B18: ARS000069|FG012|CK3-33126 | C18: ARS000069 | D18: =IFERROR(INDEX(M_User!$A$12:$J$67,MATCH(C18,M_User!$D$12:$D$67,0),3),"UNMAPPED") -> Doglas E. Shirima | E18: =IFERROR(INDEX(M_User!$A$12:$J$67,MATCH(C18,M_User!$D$12:$D$67,0),5),"UNMAPPED") -> ARS | F18: FG012 | G18: =IFERROR(INDEX(M_SKU!$A$18:$J$57,MATCH(F18,M_SKU!$B$18:$B$57,0),1),"UNKNOWN SKU") -> Krest Ginger Ale RGB 300ml | H18: CK3-33126 | I18: =SUMIF(T_Load!$U$9:$U$439,B18,T_Load!$O$9:$O$439) -> 1 | J18: =SUMIF(T_Sales!$O$9:$O$1164,B18,T_Sales!$L$9:$L$1164) -> 0.75 | K18: =I18-J18 -> 0.25 | L18: 46179 | M18: Pending Unload
A19: U-0010 | B19: ARS000069|KD001|CK4-836 | C19: ARS000069 | D19: =IFERROR(INDEX(M_User!$A$12:$J$67,MATCH(C19,M_User!$D$12:$D$67,0),3),"UNMAPPED") -> Doglas E. Shirima | E19: =IFERROR(INDEX(M_User!$A$12:$J$67,MATCH(C19,M_User!$D$12:$D$67,0),5),"UNMAPPED") -> ARS | F19: KD001 | G19: =IFERROR(INDEX(M_SKU!$A$18:$J$57,MATCH(F19,M_SKU!$B$18:$B$57,0),1),"UNKNOWN SKU") -> KNMW 500ml | H19: CK4-836 | I19: =SUMIF(T_Load!$U$9:$U$439,B19,T_Load!$O$9:$O$439) -> 200 | J19: =SUMIF(T_Sales!$O$9:$O$1164,B19,T_Sales!$L$9:$L$1164) -> 154 | K19: =I19-J19 -> 46 | L19: 46179 | M19: Pending Unload
A20: U-0011 | B20: ARS000069|KD001|CK6-978 | C20: ARS000069 | D20: =IFERROR(INDEX(M_User!$A$12:$J$67,MATCH(C20,M_User!$D$12:$D$67,0),3),"UNMAPPED") -> Doglas E. Shirima | E20: =IFERROR(INDEX(M_User!$A$12:$J$67,MATCH(C20,M_User!$D$12:$D$67,0),5),"UNMAPPED") -> ARS | F20: KD001 | G20: =IFERROR(INDEX(M_SKU!$A$18:$J$57,MATCH(F20,M_SKU!$B$18:$B$57,0),1),"UNKNOWN SKU") -> KNMW 500ml | H20: CK6-978 | I20: =SUMIF(T_Load!$U$9:$U$439,B20,T_Load!$O$9:$O$439) -> 139 | J20: =SUMIF(T_Sales!$O$9:$O$1164,B20,T_Sales!$L$9:$L$1164) -> 100 | K20: =I20-J20 -> 39 | L20: 46179 | M20: Pending Unload
A21: U-0012 | B21: ARS000069|KD001|CK6-983 | C21: ARS000069 | D21: =IFERROR(INDEX(M_User!$A$12:$J$67,MATCH(C21,M_User!$D$12:$D$67,0),3),"UNMAPPED") -> Doglas E. Shirima | E21: =IFERROR(INDEX(M_User!$A$12:$J$67,MATCH(C21,M_User!$D$12:$D$67,0),5),"UNMAPPED") -> ARS | F21: KD001 | G21: =IFERROR(INDEX(M_SKU!$A$18:$J$57,MATCH(F21,M_SKU!$B$18:$B$57,0),1),"UNKNOWN SKU") -> KNMW 500ml | H21: CK6-983 | I21: =SUMIF(T_Load!$U$9:$U$439,B21,T_Load!$O$9:$O$439) -> 1 | J21: =SUMIF(T_Sales!$O$9:$O$1164,B21,T_Sales!$L$9:$L$1164) -> 1 | K21: =I21-J21 -> 0 | L21: 46179 | M21: Pending Unload
... A433: U-0424 | B433: MOS100842|PO015|CK5-33366 | C433: MOS100842 | D433: =IFERROR(INDEX(M_User!$A$12:$J$67,MATCH(C433,M_User!$D$12:$D$67,0),3),"UNMAPPED") -> Samson Felix Ngowi | E433: =IFERROR(INDEX(M_User!$A$12:$J$67,MATCH(C433,M_User!$D$12:$D$67,0),5),"UNMAPPED") -> MOS | F433: PO015 | G433: =IFERROR(INDEX(M_SKU!$A$18:$J$57,MATCH(F433,M_SKU!$B$18:$B$57,0),1),"UNKNOWN SKU") -> Sparletta Pine Apple Pet 300ML (x 12) | H433: CK5-33366 | I433: =SUMIF(T_Load!$U$9:$U$439,B433,T_Load!$O$9:$O$439) -> 5 | J433: =SUMIF(T_Sales!$O$9:$O$1164,B433,T_Sales!$L$9:$L$1164) -> 4 | K433: =I433-J433 -> 1 | L433: 46179 | M433: Pending Unload
A436: SUMMARY
A437: Total Unload Rows: | E437: =COUNTA(A10:A433) -> 424
A438: Unique Salesmen: | E438: =SUMPRODUCT(1/COUNTIF(C10:C433,C10:C433)) -> 18
A439: Total Load Qty: | E439: =SUM(I10:I433) -> 8286
A440: Total Sales Qty: | E440: =SUM(J10:J433) -> 6616.9405
A441: Total Expected ROP: | E441: =SUM(K10:K433) -> 1669.0595
A443: Status Breakdown:
A444: Pending Unload: | E444: =COUNTIF(M10:M433,"Pending Unload") -> 400
A445: Blocked (Force-Push): | E445: =COUNTIF(M10:M433,"Blocked (Force-Push)") -> 24
A447: Scenario Verification:
A448: Joyline (MOS100802) Expected ROP — should be NEGATIVE (excess scenario): | E448: =SUMIFS(K10:K433,C10:C433,"MOS100802") -> -1.170759
A449: Riziki (MOS100645) Expected ROP — should be HIGH (shortage scenario, low sales): | E449: =SUMIFS(K10:K433,C10:C433,"MOS100645") -> 187.50225
A450: James (MOS100801) Expected ROP — should equal Load Qty (no sales): | E450: =SUMIFS(K10:K433,C10:C433,"MOS100801") -> 320

Sheet T_ROP
A1: T_ROP — Integration Page (ROP Verification)
A2: The heart of the SAP Integration & Compliance module. Clerk verifies physical stock against system Expected ROP.
A3: The ONLY manual input in this entire flow is the "Actual ROP" column (highlighted pale yellow). Everything else is automatic.
A4: Variance Logic (auto):
A5: • Variance = Expected ROP − Actual ROP
A6: • Variance = 0 → CLEAN (no further action)
A7: • Variance > 0 → SHORTAGE → POST TO DEFAULT OUTLET at depot price (creates new sale record)
A8: • Variance < 0 → EXCESS → ADJUST UNLOAD UPWARD (NO new sales; sales are immutable)
A10: Column Groups: | B10: Identification | D10: Resolved by SFA | F10: Expected (Auto) | H10: CLERK INPUT | J10: Computed | L10: Resolution | N10: State
A12: ROP ID | B12: Stock Key | C12: Salesman SAP Code | D12: Salesman Name | E12: Depot | F12: SKU Code | G12: SKU Name | H12: Batch Number | I12: Expected ROP | J12: Actual ROP (Clerk) | K12: Variance | L12: Resolution Action | M12: Default Outlet Posting Qty | N12: Unload Adjustment Qty | O12: Status | P12: Verified By | Q12: Verified On
A13: ROP-0001 | B13: ARS000069|FG001|CK3-33379 | C13: ARS000069 | D13: =IFERROR(INDEX(M_User!$A$12:$J$67,MATCH(C13,M_User!$D$12:$D$67,0),3),"UNMAPPED") -> Doglas E. Shirima | E13: =IFERROR(INDEX(M_User!$A$12:$J$67,MATCH(C13,M_User!$D$12:$D$67,0),5),"UNMAPPED") -> ARS | F13: FG001 | G13: =IFERROR(INDEX(M_SKU!$A$18:$J$57,MATCH(F13,M_SKU!$B$18:$B$57,0),1),"UNKNOWN SKU") -> Coke RGB 350ml | H13: CK3-33379 | I13: =IFERROR(INDEX(T_Unload!$K$10:$K$433,MATCH(B13,T_Unload!$B$10:$B$433,0)),0) -> 2.5674504 | J13: 2.5675 | K13: =IF(ISBLANK(J13),"",I13-J13) -> -4.9617914e-05 | L13: =IF(K13="","Awaiting Verification",IF(ABS(K13)<0.0001,"CLEAN",IF(K13>0,"Post to Default Outlet","Adjust Unload Upward"))) -> CLEAN | M13: =IF(AND(ISNUMBER(K13),K13>0.0001),K13,0) -> 0 | N13: =IF(AND(ISNUMBER(K13),K13<-0.0001),-K13,0) -> 0 | O13: Pending Verification
A14: ROP-0002 | B14: ARS000069|FG002|CK3-33372 | C14: ARS000069 | D14: =IFERROR(INDEX(M_User!$A$12:$J$67,MATCH(C14,M_User!$D$12:$D$67,0),3),"UNMAPPED") -> Doglas E. Shirima | E14: =IFERROR(INDEX(M_User!$A$12:$J$67,MATCH(C14,M_User!$D$12:$D$67,0),5),"UNMAPPED") -> ARS | F14: FG002 | G14: =IFERROR(INDEX(M_SKU!$A$18:$J$57,MATCH(F14,M_SKU!$B$18:$B$57,0),1),"UNKNOWN SKU") -> Fanta Orange RGB 350ml | H14: CK3-33372 | I14: =IFERROR(INDEX(T_Unload!$K$10:$K$433,MATCH(B14,T_Unload!$B$10:$B$433,0)),0) -> 1.0164626 | J14: 1.0165 | K14: =IF(ISBLANK(J14),"",I14-J14) -> -3.7429372e-05 | L14: =IF(K14="","Awaiting Verification",IF(ABS(K14)<0.0001,"CLEAN",IF(K14>0,"Post to Default Outlet","Adjust Unload Upward"))) -> CLEAN | M14: =IF(AND(ISNUMBER(K14),K14>0.0001),K14,0) -> 0 | N14: =IF(AND(ISNUMBER(K14),K14<-0.0001),-K14,0) -> 0 | O14: Pending Verification
A15: ROP-0003 | B15: ARS000069|FG003|CK3-33290 | C15: ARS000069 | D15: =IFERROR(INDEX(M_User!$A$12:$J$67,MATCH(C15,M_User!$D$12:$D$67,0),3),"UNMAPPED") -> Doglas E. Shirima | E15: =IFERROR(INDEX(M_User!$A$12:$J$67,MATCH(C15,M_User!$D$12:$D$67,0),5),"UNMAPPED") -> ARS | F15: FG003 | G15: =IFERROR(INDEX(M_SKU!$A$18:$J$57,MATCH(F15,M_SKU!$B$18:$B$57,0),1),"UNKNOWN SKU") -> Fanta Passion RGB 350ml | H15: CK3-33290 | I15: =IFERROR(INDEX(T_Unload!$K$10:$K$433,MATCH(B15,T_Unload!$B$10:$B$433,0)),0) -> 0.48106918 | J15: 0.4811 | K15: =IF(ISBLANK(J15),"",I15-J15) -> -3.0819353e-05 | L15: =IF(K15="","Awaiting Verification",IF(ABS(K15)<0.0001,"CLEAN",IF(K15>0,"Post to Default Outlet","Adjust Unload Upward"))) -> CLEAN | M15: =IF(AND(ISNUMBER(K15),K15>0.0001),K15,0) -> 0 | N15: =IF(AND(ISNUMBER(K15),K15<-0.0001),-K15,0) -> 0 | O15: Pending Verification
A16: ROP-0004 | B16: ARS000069|FG004|CK5-33354 | C16: ARS000069 | D16: =IFERROR(INDEX(M_User!$A$12:$J$67,MATCH(C16,M_User!$D$12:$D$67,0),3),"UNMAPPED") -> Doglas E. Shirima | E16: =IFERROR(INDEX(M_User!$A$12:$J$67,MATCH(C16,M_User!$D$12:$D$67,0),5),"UNMAPPED") -> ARS | F16: FG004 | G16: =IFERROR(INDEX(M_SKU!$A$18:$J$57,MATCH(F16,M_SKU!$B$18:$B$57,0),1),"UNKNOWN SKU") -> Fanta Pineapple RGB 350ml | H16: CK5-33354 | I16: =IFERROR(INDEX(T_Unload!$K$10:$K$433,MATCH(B16,T_Unload!$B$10:$B$433,0)),0) -> 0.57756435 | J16: 0.5776 | K16: =IF(ISBLANK(J16),"",I16-J16) -> -3.5650565e-05 | L16: =IF(K16="","Awaiting Verification",IF(ABS(K16)<0.0001,"CLEAN",IF(K16>0,"Post to Default Outlet","Adjust Unload Upward"))) -> CLEAN | M16: =IF(AND(ISNUMBER(K16),K16>0.0001),K16,0) -> 0 | N16: =IF(AND(ISNUMBER(K16),K16<-0.0001),-K16,0) -> 0 | O16: Pending Verification
A17: ROP-0005 | B17: ARS000069|FG006|CK3-33306 | C17: ARS000069 | D17: =IFERROR(INDEX(M_User!$A$12:$J$67,MATCH(C17,M_User!$D$12:$D$67,0),3),"UNMAPPED") -> Doglas E. Shirima | E17: =IFERROR(INDEX(M_User!$A$12:$J$67,MATCH(C17,M_User!$D$12:$D$67,0),5),"UNMAPPED") -> ARS | F17: FG006 | G17: =IFERROR(INDEX(M_SKU!$A$18:$J$57,MATCH(F17,M_SKU!$B$18:$B$57,0),1),"UNKNOWN SKU") -> Sprite 350ml | H17: CK3-33306 | I17: =IFERROR(INDEX(T_Unload!$K$10:$K$433,MATCH(B17,T_Unload!$B$10:$B$433,0)),0) -> 0.4583 | J17: 0.4583 | K17: =IF(ISBLANK(J17),"",I17-J17) -> -5.5511151e-17 | L17: =IF(K17="","Awaiting Verification",IF(ABS(K17)<0.0001,"CLEAN",IF(K17>0,"Post to Default Outlet","Adjust Unload Upward"))) -> CLEAN | M17: =IF(AND(ISNUMBER(K17),K17>0.0001),K17,0) -> 0 | N17: =IF(AND(ISNUMBER(K17),K17<-0.0001),-K17,0) -> 0 | O17: Pending Verification
A18: ROP-0006 | B18: ARS000069|FG009|CK3-33348 | C18: ARS000069 | D18: =IFERROR(INDEX(M_User!$A$12:$J$67,MATCH(C18,M_User!$D$12:$D$67,0),3),"UNMAPPED") -> Doglas E. Shirima | E18: =IFERROR(INDEX(M_User!$A$12:$J$67,MATCH(C18,M_User!$D$12:$D$67,0),5),"UNMAPPED") -> ARS | F18: FG009 | G18: =IFERROR(INDEX(M_SKU!$A$18:$J$57,MATCH(F18,M_SKU!$B$18:$B$57,0),1),"UNKNOWN SKU") -> Krest Bitter Lemon RGB 300ml | H18: CK3-33348 | I18: =IFERROR(INDEX(T_Unload!$K$10:$K$433,MATCH(B18,T_Unload!$B$10:$B$433,0)),0) -> 0.58792761 | J18: 0.5879 | K18: =IF(ISBLANK(J18),"",I18-J18) -> 2.7611692e-05 | L18: =IF(K18="","Awaiting Verification",IF(ABS(K18)<0.0001,"CLEAN",IF(K18>0,"Post to Default Outlet","Adjust Unload Upward"))) -> CLEAN | M18: =IF(AND(ISNUMBER(K18),K18>0.0001),K18,0) -> 0 | N18: =IF(AND(ISNUMBER(K18),K18<-0.0001),-K18,0) -> 0 | O18: Pending Verification
A19: ROP-0007 | B19: ARS000069|FG010|CK3-33301 | C19: ARS000069 | D19: =IFERROR(INDEX(M_User!$A$12:$J$67,MATCH(C19,M_User!$D$12:$D$67,0),3),"UNMAPPED") -> Doglas E. Shirima | E19: =IFERROR(INDEX(M_User!$A$12:$J$67,MATCH(C19,M_User!$D$12:$D$67,0),5),"UNMAPPED") -> ARS | F19: FG010 | G19: =IFERROR(INDEX(M_SKU!$A$18:$J$57,MATCH(F19,M_SKU!$B$18:$B$57,0),1),"UNKNOWN SKU") -> Krest Club Soda RGB 300ml | H19: CK3-33301 | I19: =IFERROR(INDEX(T_Unload!$K$10:$K$433,MATCH(B19,T_Unload!$B$10:$B$433,0)),0) -> 0.74296988 | J19: 0.743 | K19: =IF(ISBLANK(J19),"",I19-J19) -> -3.0122311e-05 | L19: =IF(K19="","Awaiting Verification",IF(ABS(K19)<0.0001,"CLEAN",IF(K19>0,"Post to Default Outlet","Adjust Unload Upward"))) -> CLEAN | M19: =IF(AND(ISNUMBER(K19),K19>0.0001),K19,0) -> 0 | N19: =IF(AND(ISNUMBER(K19),K19<-0.0001),-K19,0) -> 0 | O19: Pending Verification
